Traceback (most recent call last):
  File "/Library/Frameworks/Python.framework/Versions/3.10/lib/python3.10/site-packages/jupyter_cache/executors/utils.py", line 51, in single_nb_execution
    executenb(
  File "/Library/Frameworks/Python.framework/Versions/3.10/lib/python3.10/site-packages/nbclient/client.py", line 1204, in execute
    return NotebookClient(nb=nb, resources=resources, km=km, **kwargs).execute()
  File "/Library/Frameworks/Python.framework/Versions/3.10/lib/python3.10/site-packages/nbclient/util.py", line 84, in wrapped
    return just_run(coro(*args, **kwargs))
  File "/Library/Frameworks/Python.framework/Versions/3.10/lib/python3.10/site-packages/nbclient/util.py", line 62, in just_run
    return loop.run_until_complete(coro)
  File "/Library/Frameworks/Python.framework/Versions/3.10/lib/python3.10/asyncio/base_events.py", line 649, in run_until_complete
    return future.result()
  File "/Library/Frameworks/Python.framework/Versions/3.10/lib/python3.10/site-packages/nbclient/client.py", line 663, in async_execute
    await self.async_execute_cell(
  File "/Library/Frameworks/Python.framework/Versions/3.10/lib/python3.10/site-packages/nbclient/client.py", line 965, in async_execute_cell
    await self._check_raise_for_error(cell, cell_index, exec_reply)
  File "/Library/Frameworks/Python.framework/Versions/3.10/lib/python3.10/site-packages/nbclient/client.py", line 862, in _check_raise_for_error
    raise CellExecutionError.from_cell_and_msg(cell, exec_reply_content)
nbclient.exceptions.CellExecutionError: An error occurred while executing the following cell:
------------------
numeric=['Age','DailyRate','DistanceFromHome',
'Education','EmployeeCount','EmployeeNumber',
'EnvironmentSatisfaction','HourlyRate','JobInvolvement',
'JobLevel','JobSatisfaction','MonthlyIncome','MonthlyRate','NumCompaniesWorked',
'PercentSalaryHike','PerformanceRating','RelationshipSatisfaction','StandardHours',	
'StockOptionLevel','TotalWorkingYears','TrainingTimesLastYear','WorkLifeBalance',	
'YearsAtCompany','YearsInCurrentRole','YearsSinceLastPromotion','YearsWithCurrManager',
]
numeric
for i in numeric:
    #print(attrition[i])
    print(i,':', stats.shapiro(attrition[i]))
------------------

[0;31m---------------------------------------------------------------------------[0m
[0;31mNameError[0m                                 Traceback (most recent call last)
Cell [0;32mIn [13], line 12[0m
[1;32m      9[0m numeric
[1;32m     10[0m [38;5;28;01mfor[39;00m i [38;5;129;01min[39;00m numeric:
[1;32m     11[0m     [38;5;66;03m#print(attrition[i])[39;00m
[0;32m---> 12[0m     [38;5;28mprint[39m(i,[38;5;124m'[39m[38;5;124m:[39m[38;5;124m'[39m, [43mstats[49m[38;5;241m.[39mshapiro(attrition[i]))

[0;31mNameError[0m: name 'stats' is not defined
NameError: name 'stats' is not defined

